Workbook

Sheet Overview
A1: Overview
A3: About This Report
A4: This workbook ranks DAST (dynamic application security testing) vendors against a weighted set of evaluation criteria, blending automated desk research with hands-on benchmark testing where available.
A5: Reviewers can weigh in on any criterion on that vendor's tab and resolve disagreements with the automated score; resolved scores take precedence in the totals below. Claim a reviewer slot once on the "Reviewers" tab and it applies automatically to every vendor tab.
A6: See the "How This Works" tab (last tab) for the full methodology, scoring formulas, and definitions.
A8: Vendor | B8: Coverage | C8: Detection Quality | D8: Production Safety & Operability | E8: Developer Experience | F8: Reporting & Extensibility | G8: Deployment & Data Governance | H8: Weighted Avg Score | I8: Total Achieved / Available
A9: Invicti | B9: =IF('invicti'!E38=0,"Pending",'invicti'!C38/'invicti'!E38*5) | C9: =IF('invicti'!E39=0,"Pending",'invicti'!C39/'invicti'!E39*5) | D9: =IF('invicti'!E40=0,"Pending",'invicti'!C40/'invicti'!E40*5) | E9: =IF('invicti'!E41=0,"Pending",'invicti'!C41/'invicti'!E41*5) | F9: =IF('invicti'!E42=0,"Pending",'invicti'!C42/'invicti'!E42*5) | G9: =IF('invicti'!E43=0,"Pending",'invicti'!C43/'invicti'!E43*5) | H9: =IF('invicti'!E44=0,"Pending",'invicti'!C44/'invicti'!E44*5) | I9: ='invicti'!D44
A10: StackHawk | B10: =IF('stackhawk'!E38=0,"Pending",'stackhawk'!C38/'stackhawk'!E38*5) | C10: =IF('stackhawk'!E39=0,"Pending",'stackhawk'!C39/'stackhawk'!E39*5) | D10: =IF('stackhawk'!E40=0,"Pending",'stackhawk'!C40/'stackhawk'!E40*5) | E10: =IF('stackhawk'!E41=0,"Pending",'stackhawk'!C41/'stackhawk'!E41*5) | F10: =IF('stackhawk'!E42=0,"Pending",'stackhawk'!C42/'stackhawk'!E42*5) | G10: =IF('stackhawk'!E43=0,"Pending",'stackhawk'!C43/'stackhawk'!E43*5) | H10: =IF('stackhawk'!E44=0,"Pending",'stackhawk'!C44/'stackhawk'!E44*5) | I10: ='stackhawk'!D44
A11: HCL AppScan | B11: =IF('hcl-appscan'!E38=0,"Pending",'hcl-appscan'!C38/'hcl-appscan'!E38*5) | C11: =IF('hcl-appscan'!E39=0,"Pending",'hcl-appscan'!C39/'hcl-appscan'!E39*5) | D11: =IF('hcl-appscan'!E40=0,"Pending",'hcl-appscan'!C40/'hcl-appscan'!E40*5) | E11: =IF('hcl-appscan'!E41=0,"Pending",'hcl-appscan'!C41/'hcl-appscan'!E41*5) | F11: =IF('hcl-appscan'!E42=0,"Pending",'hcl-appscan'!C42/'hcl-appscan'!E42*5) | G11: =IF('hcl-appscan'!E43=0,"Pending",'hcl-appscan'!C43/'hcl-appscan'!E43*5) | H11: =IF('hcl-appscan'!E44=0,"Pending",'hcl-appscan'!C44/'hcl-appscan'!E44*5) | I11: ='hcl-appscan'!D44
A12: Checkmarx DAST | B12: =IF('checkmarx-dast'!E38=0,"Pending",'checkmarx-dast'!C38/'checkmarx-dast'!E38*5) | C12: =IF('checkmarx-dast'!E39=0,"Pending",'checkmarx-dast'!C39/'checkmarx-dast'!E39*5) | D12: =IF('checkmarx-dast'!E40=0,"Pending",'checkmarx-dast'!C40/'checkmarx-dast'!E40*5) | E12: =IF('checkmarx-dast'!E41=0,"Pending",'checkmarx-dast'!C41/'checkmarx-dast'!E41*5) | F12: =IF('checkmarx-dast'!E42=0,"Pending",'checkmarx-dast'!C42/'checkmarx-dast'!E42*5) | G12: =IF('checkmarx-dast'!E43=0,"Pending",'checkmarx-dast'!C43/'checkmarx-dast'!E43*5) | H12: =IF('checkmarx-dast'!E44=0,"Pending",'checkmarx-dast'!C44/'checkmarx-dast'!E44*5) | I12: ='checkmarx-dast'!D44
A13: Veracode Dynamic Analysis | B13: =IF('veracode'!E38=0,"Pending",'veracode'!C38/'veracode'!E38*5) | C13: =IF('veracode'!E39=0,"Pending",'veracode'!C39/'veracode'!E39*5) | D13: =IF('veracode'!E40=0,"Pending",'veracode'!C40/'veracode'!E40*5) | E13: =IF('veracode'!E41=0,"Pending",'veracode'!C41/'veracode'!E41*5) | F13: =IF('veracode'!E42=0,"Pending",'veracode'!C42/'veracode'!E42*5) | G13: =IF('veracode'!E43=0,"Pending",'veracode'!C43/'veracode'!E43*5) | H13: =IF('veracode'!E44=0,"Pending",'veracode'!C44/'veracode'!E44*5) | I13: ='veracode'!D44
A14: OWASP ZAP | B14: =IF('zap'!E38=0,"Pending",'zap'!C38/'zap'!E38*5) | C14: =IF('zap'!E39=0,"Pending",'zap'!C39/'zap'!E39*5) | D14: =IF('zap'!E40=0,"Pending",'zap'!C40/'zap'!E40*5) | E14: =IF('zap'!E41=0,"Pending",'zap'!C41/'zap'!E41*5) | F14: =IF('zap'!E42=0,"Pending",'zap'!C42/'zap'!E42*5) | G14: =IF('zap'!E43=0,"Pending",'zap'!C43/'zap'!E43*5) | H14: =IF('zap'!E44=0,"Pending",'zap'!C44/'zap'!E44*5) | I14: ='zap'!D44
A15: Rapid7 InsightAppSec | B15: =IF('rapid7-insightappsec'!E38=0,"Pending",'rapid7-insightappsec'!C38/'rapid7-insightappsec'!E38*5) | C15: =IF('rapid7-insightappsec'!E39=0,"Pending",'rapid7-insightappsec'!C39/'rapid7-insightappsec'!E39*5) | D15: =IF('rapid7-insightappsec'!E40=0,"Pending",'rapid7-insightappsec'!C40/'rapid7-insightappsec'!E40*5) | E15: =IF('rapid7-insightappsec'!E41=0,"Pending",'rapid7-insightappsec'!C41/'rapid7-insightappsec'!E41*5) | F15: =IF('rapid7-insightappsec'!E42=0,"Pending",'rapid7-insightappsec'!C42/'rapid7-insightappsec'!E42*5) | G15: =IF('rapid7-insightappsec'!E43=0,"Pending",'rapid7-insightappsec'!C43/'rapid7-insightappsec'!E43*5) | H15: =IF('rapid7-insightappsec'!E44=0,"Pending",'rapid7-insightappsec'!C44/'rapid7-insightappsec'!E44*5) | I15: ='rapid7-insightappsec'!D44
A16: Nuclei | B16: =IF('nuclei'!E38=0,"Pending",'nuclei'!C38/'nuclei'!E38*5) | C16: =IF('nuclei'!E39=0,"Pending",'nuclei'!C39/'nuclei'!E39*5) | D16: =IF('nuclei'!E40=0,"Pending",'nuclei'!C40/'nuclei'!E40*5) | E16: =IF('nuclei'!E41=0,"Pending",'nuclei'!C41/'nuclei'!E41*5) | F16: =IF('nuclei'!E42=0,"Pending",'nuclei'!C42/'nuclei'!E42*5) | G16: =IF('nuclei'!E43=0,"Pending",'nuclei'!C43/'nuclei'!E43*5) | H16: =IF('nuclei'!E44=0,"Pending",'nuclei'!C44/'nuclei'!E44*5) | I16: ='nuclei'!D44
A17: Qualys WAS | B17: =IF('qualys-was'!E38=0,"Pending",'qualys-was'!C38/'qualys-was'!E38*5) | C17: =IF('qualys-was'!E39=0,"Pending",'qualys-was'!C39/'qualys-was'!E39*5) | D17: =IF('qualys-was'!E40=0,"Pending",'qualys-was'!C40/'qualys-was'!E40*5) | E17: =IF('qualys-was'!E41=0,"Pending",'qualys-was'!C41/'qualys-was'!E41*5) | F17: =IF('qualys-was'!E42=0,"Pending",'qualys-was'!C42/'qualys-was'!E42*5) | G17: =IF('qualys-was'!E43=0,"Pending",'qualys-was'!C43/'qualys-was'!E43*5) | H17: =IF('qualys-was'!E44=0,"Pending",'qualys-was'!C44/'qualys-was'!E44*5) | I17: ='qualys-was'!D44

Sheet Reviewers
A1: Reviewers
A3: Claim a slot by filling in your name and role below — it appears automatically on every vendor tab.
A4: Please don't overwrite an existing reviewer's name/role — you may be reassigning someone else's already-entered scores to yourself.
A5: Slot | B5: Name | C5: Role / Title
A6: 1
A7: 2
A8: 3
A9: 4
A10: 5

Sheet invicti
A1: Invicti
G2: =IF(Reviewers!B6="","Unassigned — see Reviewers tab",Reviewers!B6&" - "&Reviewers!C6) | J2: =IF(Reviewers!B7="","Unassigned — see Reviewers tab",Reviewers!B7&" - "&Reviewers!C7) | M2: =IF(Reviewers!B8="","Unassigned — see Reviewers tab",Reviewers!B8&" - "&Reviewers!C8) | P2: =IF(Reviewers!B9="","Unassigned — see Reviewers tab",Reviewers!B9&" - "&Reviewers!C9) | S2: =IF(Reviewers!B10="","Unassigned — see Reviewers tab",Reviewers!B10&" - "&Reviewers!C10)
A3: Criterion | B3: Category | C3: Weight | D3: Automated Score | E3: Automated Evidence | F3: Automated Confidence | G3: Score | H3: Dispute? | I3: Rationale | J3: Score | K3: Dispute? | L3: Rationale | M3: Score | N3: Dispute? | O3: Rationale | P3: Score | Q3: Dispute? | R3: Rationale | S3: Score | T3: Dispute? | U3: Rationale | V3: Resolved Score | W3: Resolved By | X3: Resolved Timestamp | Y3: Automated vs. Resolved Delta | Z3: _criterion_id | AA3: _pending | AB3: _effective_score
A4: Detection Accuracy | B4: Detection Quality | C4: 7 | D4: 4 | E4: VENDOR CLAIM, not independently verified: Proof-Based Scanning claims 99.98% detection accuracy. Source: invicti.com/features/proof-based-scanning | F4: paper | Y4: =IF(ISBLANK(V4),"",V4-D4) | Z4: detection-accuracy | AA4: 0 | AB4: =IF(ISBLANK(V4),D4,V4)
A5: Authentication & Session Handling | B5: Coverage | C5: 6 | D5: 4 | E5: Supports API Key, Bearer Token, JWT, Basic Auth, and OAuth 2.0; explicit messaging on handling SSO/MFA for thorough authenticated testing. Source: invicti.com/features/api-security-testing | F5: paper | Y5: =IF(ISBLANK(V5),"",V5-D5) | Z5: auth-session-handling | AA5: 0 | AB5: =IF(ISBLANK(V5),D5,V5)
A6: Safe Production Scanning | B6: Production Safety & Operability | C6: 6 | D6: 4 | E6: Revised up with real citations: a dedicated 'Scanning Production Environments' guide exists, passive security checks issue no extra HTTP requests, and scan speed is configurable across four tiers (Sequential/Slow/Moderate/Fast) specifically to handle rate-limited/production environments -- more concrete than initially found, though Invicti's own docs still caveat that active checks can be invasive even though non-destructive. Source: invicti.com/support/scanning-production-environment, docs.invicti.com/ip/target-scan-configuration | F6: paper | Y6: =IF(ISBLANK(V6),"",V6-D6) | Z6: safe-prod-scanning | AA6: 0 | AB6: =IF(ISBLANK(V6),D6,V6)
A7: API/SPA Coverage | B7: Coverage | C7: 5 | D7: 4.5 | E7: Full browser-engine crawling accurately scans SPAs (jQuery/AngularJS), executing JS and parsing dynamic elements; REST/SOAP/GraphQL support with automatic schema/introspection discovery even without an imported schema. Source: invicti.com/support/scanning-graphql-api, invicti.com/features/advanced-website-crawling-technologies | F7: paper | Y7: =IF(ISBLANK(V7),"",V7-D7) | Z7: api-spa-coverage | AA7: 0 | AB7: =IF(ISBLANK(V7),D7,V7)
A8: CI/CD-Native Fit | B8: Production Safety & Operability | C8: 5 | D8: 5 | E8: Native integration across GitHub Actions, Jenkins, GitLab CI, Azure DevOps, CircleCI, Bamboo, TeamCity, and Bitbucket Pipelines via a Docker-based scan-cli container configured entirely through environment variables; explicit exit-code-based build-gating and branch-protection/deployment-gate workflows. Source: invicti.com/support/integrating-invicti-enterprise-github-actions, invicti.com/blog/web-security/api-security-testing-cicd-integration | F8: paper | Y8: =IF(ISBLANK(V8),"",V8-D8) | Z8: cicd-native-fit | AA8: 0 | AB8: =IF(ISBLANK(V8),D8,V8)
A9: Deployment Model & Data Residency | B9: Deployment & Data Governance | C9: 5 | D9: 4.5 | E9: Three deployment options: cloud-hosted, on-premises, and hybrid; on-prem supports fully air-gapped networks with no internet connectivity and explicit HIPAA/PCI-DSS/GDPR data-residency compliance. Source: invicti.com/pci-asv-scanner | F9: paper | Y9: =IF(ISBLANK(V9),"",V9-D9) | Z9: deployment-model-data-residency | AA9: 0 | AB9: =IF(ISBLANK(V9),D9,V9)
A10: Legacy Application & Protocol Support | B10: Coverage | C10: 5 | D10: 3 | E10: SOAP API scanning explicitly supported via WSDL schema parsing (file or URL), and ASP.NET applications are explicitly detected/supported including JS-heavy interfaces; no JSP-specific accuracy claims found beyond general protocol coverage. Source: invicti.com/soap-scanner, invicti.com/web-vulnerability-scanner/vulnerabilities/aspnet-identified | F10: paper | Y10: =IF(ISBLANK(V10),"",V10-D10) | Z10: legacy-app-protocol-support | AA10: 0 | AB10: =IF(ISBLANK(V10),D10,V10)
A11: Business Logic & Workflow Vulnerability Detection | B11: Coverage | C11: 4 | D11: 4 | E11: Named 'Business Logic Recorder' (BLR) for multi-step workflow/form testing, plus stateful API scanning maintaining auth/session context across multi-step API calls to catch BOLA/BFLA. Not a full 5: BLR's own docs note different recordings don't rely on/sequence with one another, limiting true cross-recording attack chains. Source: docs.invicti.com/ie-is/business-logic-recorder-invicti, invicti.com/blog/web-security/automate-api-security-testing | F11: paper | Y11: =IF(ISBLANK(V11),"",V11-D11) | Z11: business-logic-workflow-detection | AA11: 0 | AB11: =IF(ISBLANK(V11),D11,V11)
A12: Compliance & Standards Mapping | B12: Detection Quality | C12: 4 | D12: 4.5 | E12: Built-in compliance reporting for PCI DSS, ISO 27001, HIPAA, and SOC 2; PCI DSS reports explicitly show which findings violate specific control sections. Source: invicti.com/blog/web-security/how-dast-supports-compliance-pci-dss-iso27001-hipaa-soc2 | F12: paper | Y12: =IF(ISBLANK(V12),"",V12-D12) | Z12: compliance-standards-mapping | AA12: 0 | AB12: =IF(ISBLANK(V12),D12,V12)
A13: Noise / False-Positive Rate | B13: Detection Quality | C13: 4 | D13: 4.5 | E13: Proof-Based Scanning automatically re-exploits detected vulnerabilities in a safe way to confirm they're real (not theoretical), specifically designed to eliminate false positives before they reach a triage queue. Source: invicti.com/features/proof-based-scanning | F13: paper | Y13: =IF(ISBLANK(V13),"",V13-D13) | Z13: false-positive-rate | AA13: 0 | AB13: =IF(ISBLANK(V13),D13,V13)
A14: Shadow/Zombie API Discovery | B14: Coverage | C14: 4 | D14: 4 | E14: Dedicated API Discovery product feature for surfacing undocumented/shadow APIs. Source: invicti.com/solutions/api-discovery | F14: paper | Y14: =IF(ISBLANK(V14),"",V14-D14) | Z14: shadow-api-discovery | AA14: 0 | AB14: =IF(ISBLANK(V14),D14,V14)
A15: Triage & Remediation Guidance | B15: Developer Experience | C15: 4 | D15: 4.5 | E15: AI-driven remediation guidance delivers code-level fix suggestions tailored to the specific finding, in context, rather than generic secure-coding advice. Source: invicti.com/features/developer-guidance | F15: paper | Y15: =IF(ISBLANK(V15),"",V15-D15) | Z15: triage-remediation-guidance | AA15: 0 | AB15: =IF(ISBLANK(V15),D15,V15)
... A36: Auto-Remediation / Auto-PR | B36: Developer Experience | C36: 0 | D36: 3.5 | E36: Auto-assigns confirmed vulnerabilities to developers with AI-driven fix recommendations they can apply and validate directly in their workflow, but no explicit auto-opened-PR capability confirmed. Source: invicti.com/product/ai-powered-application-security | F36: paper | Y36: =IF(ISBLANK(V36),"",V36-D36) | Z36: auto-remediation-pr | AA36: 0 | AB36: =IF(ISBLANK(V36),D36,V36)
A37: Summary
A38: Coverage | C38: =SUMPRODUCT((B4:B36="Coverage")*C4:C36*AB4:AB36*(1-AA4:AA36))/5 | D38: =TEXT(C38,"0.0")&"/"&TEXT(E38,"0")&" available points" | E38: =SUMPRODUCT((B4:B36="Coverage")*C4:C36*(1-AA4:AA36))
A39: Detection Quality | C39: =SUMPRODUCT((B4:B36="Detection Quality")*C4:C36*AB4:AB36*(1-AA4:AA36))/5 | D39: =TEXT(C39,"0.0")&"/"&TEXT(E39,"0")&" available points" | E39: =SUMPRODUCT((B4:B36="Detection Quality")*C4:C36*(1-AA4:AA36))
A40: Production Safety & Operability | C40: =SUMPRODUCT((B4:B36="Production Safety & Operability")*C4:C36*AB4:AB36*(1-AA4:AA36))/5 | D40: =TEXT(C40,"0.0")&"/"&TEXT(E40,"0")&" available points" | E40: =SUMPRODUCT((B4:B36="Production Safety & Operability")*C4:C36*(1-AA4:AA36))
A41: Developer Experience | C41: =SUMPRODUCT((B4:B36="Developer Experience")*C4:C36*AB4:AB36*(1-AA4:AA36))/5 | D41: =TEXT(C41,"0.0")&"/"&TEXT(E41,"0")&" available points" | E41: =SUMPRODUCT((B4:B36="Developer Experience")*C4:C36*(1-AA4:AA36))
A42: Reporting & Extensibility | C42: =SUMPRODUCT((B4:B36="Reporting & Extensibility")*C4:C36*AB4:AB36*(1-AA4:AA36))/5 | D42: =TEXT(C42,"0.0")&"/"&TEXT(E42,"0")&" available points" | E42: =SUMPRODUCT((B4:B36="Reporting & Extensibility")*C4:C36*(1-AA4:AA36))
A43: Deployment & Data Governance | C43: =SUMPRODUCT((B4:B36="Deployment & Data Governance")*C4:C36*AB4:AB36*(1-AA4:AA36))/5 | D43: =TEXT(C43,"0.0")&"/"&TEXT(E43,"0")&" available points" | E43: =SUMPRODUCT((B4:B36="Deployment & Data Governance")*C4:C36*(1-AA4:AA36))
A44: Weighted Total | C44: =SUMPRODUCT(C4:C36,AB4:AB36,(1-AA4:AA36))/5 | D44: =TEXT(C44,"0.0")&"/"&TEXT(E44,"0")&" available points" | E44: =SUMPRODUCT(C4:C36,(1-AA4:AA36))

Sheet veracode
A1: Veracode Dynamic Analysis
G2: =IF(Reviewers!B6="","Unassigned — see Reviewers tab",Reviewers!B6&" - "&Reviewers!C6) | J2: =IF(Reviewers!B7="","Unassigned — see Reviewers tab",Reviewers!B7&" - "&Reviewers!C7) | M2: =IF(Reviewers!B8="","Unassigned — see Reviewers tab",Reviewers!B8&" - "&Reviewers!C8) | P2: =IF(Reviewers!B9="","Unassigned — see Reviewers tab",Reviewers!B9&" - "&Reviewers!C9) | S2: =IF(Reviewers!B10="","Unassigned — see Reviewers tab",Reviewers!B10&" - "&Reviewers!C10)
A3: Criterion | B3: Category | C3: Weight | D3: Automated Score | E3: Automated Evidence | F3: Automated Confidence | G3: Score | H3: Dispute? | I3: Rationale | J3: Score | K3: Dispute? | L3: Rationale | M3: Score | N3: Dispute? | O3: Rationale | P3: Score | Q3: Dispute? | R3: Rationale | S3: Score | T3: Dispute? | U3: Rationale | V3: Resolved Score | W3: Resolved By | X3: Resolved Timestamp | Y3: Automated vs. Resolved Delta | Z3: _criterion_id | AA3: _pending | AB3: _effective_score
A4: Detection Accuracy | B4: Detection Quality | C4: 7 | D4: 3 | E4: No specific independent detection-rate benchmark found for Veracode's DAST specifically; scored from general enterprise-platform positioning and market recognition (a 9x Gartner Magic Quadrant Leader for Application Security Testing) rather than a cited accuracy number. Source: veracode.com/products/dynamic-analysis-dast, securityscientist.net/blog/12-questions-and-answers-about-veracode-dast | F4: paper | Y4: =IF(ISBLANK(V4),"",V4-D4) | Z4: detection-accuracy | AA4: 0 | AB4: =IF(ISBLANK(V4),D4,V4)
A5: Authentication & Session Handling | B5: Coverage | C5: 6 | D5: 3.5 | E5: Selenium-based crawl scripts handle complex authentication and multi-step workflows; form-based login, OAuth, and API tokens supported -- but the same independent review flags complex authentication flows as a real limitation area. Source: securityscientist.net/blog/12-questions-and-answers-about-veracode-dast | F5: paper | Y5: =IF(ISBLANK(V5),"",V5-D5) | Z5: auth-session-handling | AA5: 0 | AB5: =IF(ISBLANK(V5),D5,V5)
A6: Safe Production Scanning | B6: Production Safety & Operability | C6: 6 | D6: 3 | E6: Internal Scanning Management (ISM) enables scanning behind firewalls and in staging environments, but no explicit passive-only/rate-limited safe-mode claim for live production traffic found. Source: veracode.com/products/dynamic-analysis-dast | F6: paper | Y6: =IF(ISBLANK(V6),"",V6-D6) | Z6: safe-prod-scanning | AA6: 0 | AB6: =IF(ISBLANK(V6),D6,V6)
A7: Legacy Application & Protocol Support | B7: Coverage | C7: 5 | D7: 3 | E7: Veracode DAST scans SOAP APIs after translating the WSDL specification into a Veracode-supported spec format (Postman Collection/OpenAPI) -- real coverage with real translation friction, matching rubric level 3 rather than full parity. Modern JS SPA support came via the 2022 Crashtest Security acquisition, underscoring legacy-stack support is comparatively less native. Source: appsecsanta.com/veracode-dast, docs.veracode.com/r/Scan_APIs | F7: paper | Y7: =IF(ISBLANK(V7),"",V7-D7) | Z7: legacy-app-protocol-support | AA7: 0 | AB7: =IF(ISBLANK(V7),D7,V7)
A8: API/SPA Coverage | B8: Coverage | C8: 5 | D8: 3.5 | E8: REST/SOAP/GraphQL with OpenAPI import; SPA support (React/Angular/Vue) added via 2022 Crashtest Security acquisition with full browser rendering and DOM-based XSS detection -- but independent review notes DAST coverage is 'limited for SPAs, GraphQL APIs, and complex authentication flows' compared to specialized alternatives. Source: docs.veracode.com/r/Scan_web_applications_and_APIs, securityscientist.net/blog/12-questions-and-answers-about-veracode-dast | F8: paper | Y8: =IF(ISBLANK(V8),"",V8-D8) | Z8: api-spa-coverage | AA8: 0 | AB8: =IF(ISBLANK(V8),D8,V8)
A9: CI/CD-Native Fit | B9: Production Safety & Operability | C9: 5 | D9: 4 | E9: Explicit CI/CD pipeline integration supporting daily/weekly automated scans across development stages; Pipeline Scan output format for automation. Source: veracode.com/products/dynamic-analysis-dast | F9: paper | Y9: =IF(ISBLANK(V9),"",V9-D9) | Z9: cicd-native-fit | AA9: 0 | AB9: =IF(ISBLANK(V9),D9,V9)
A10: Deployment Model & Data Residency | B10: Deployment & Data Governance | C10: 5 | D10: 3 | E10: Internal Scanning Management (ISM) gives some on-prem-adjacent control for behind-firewall/staging scanning, but the core platform is SaaS-first (cloud-based); no full on-prem or air-gapped deployment option found like Invicti/ZAP offer. Source: veracode.com/products/dynamic-analysis-dast | F10: paper | Y10: =IF(ISBLANK(V10),"",V10-D10) | Z10: deployment-model-data-residency | AA10: 0 | AB10: =IF(ISBLANK(V10),D10,V10)
A11: Shadow/Zombie API Discovery | B11: Coverage | C11: 4 | D11: 4 | E11: Veracode EASM's Deep Discovery scan specifically surfaces unknown/unmanaged internet-facing assets and endpoints beyond a predefined list. Verified by independent gap-check after the original research missed this branded product. Source: veracode.com/veracode-external-attack-surface-management, docs.veracode.com/r/Discover_your_attack_surface | F11: paper | Y11: =IF(ISBLANK(V11),"",V11-D11) | Z11: shadow-api-discovery | AA11: 0 | AB11: =IF(ISBLANK(V11),D11,V11)
A12: Business Logic & Workflow Vulnerability Detection | B12: Coverage | C12: 4 | D12: 3 | E12: Explicitly claims to probe endpoints and entire workflows to validate business logic is developed securely, detecting business-logic vulnerabilities SAST misses -- real but generic capability, not purpose-built like a dedicated multi-role authorization-testing engine. Source: veracode.com/products/dynamic-analysis-dast | F12: paper | Y12: =IF(ISBLANK(V12),"",V12-D12) | Z12: business-logic-workflow-detection | AA12: 0 | AB12: =IF(ISBLANK(V12),D12,V12)
A13: Compliance & Standards Mapping | B13: Detection Quality | C13: 4 | D13: 4.5 | E13: Unified compliance reporting across SAST/DAST/SCA on one platform; real FedRAMP Moderate Authority to Operate (ATO) granted March 2022, a government-grade authorization uncommon among DAST vendors. Source: veracode.com/application-security-compliance, veracode.com/about/certifications | F13: paper | Y13: =IF(ISBLANK(V13),"",V13-D13) | Z13: compliance-standards-mapping | AA13: 0 | AB13: =IF(ISBLANK(V13),D13,V13)
A14: Noise / False-Positive Rate | B14: Detection Quality | C14: 4 | D14: 4.5 | E14: VENDOR CLAIM, not independently verified: <5% false-positive rate, with real-time actionable feedback. Source: veracode.com/products/dynamic-analysis-dast | F14: paper | Y14: =IF(ISBLANK(V14),"",V14-D14) | Z14: false-positive-rate | AA14: 0 | AB14: =IF(ISBLANK(V14),D14,V14)
A15: Triage & Remediation Guidance | B15: Developer Experience | C15: 4 | D15: 4 | E15: Line-of-code-specific findings identification with remediation instructions; VeraCustomTriage community tool generates a custom remediation plan (.xlsx) with internal workflow links, wiki references, and code snippets. Source: docs.veracode.com/r/Veracode_Integrations, github.com/veracode/Veracode-Community-Projects | F15: paper | Y15: =IF(ISBLANK(V15),"",V15-D15) | Z15: triage-remediation-guidance | AA15: 0 | AB15: =IF(ISBLANK(V15),D15,V15)
... A36: Incremental / Differential Scanning | B36: Production Safety & Operability | C36: 0 | D36: 3 | E36: Veracode DAST scan configuration supports allowlist/blocklist and subdirectory-level URL scoping to restrict scans to specific paths, matching rubric level 3 exactly. No automatic change-detection-since-last-scan found -- the 'Similarity Threshold' feature dedupes within one scan, not across scans. Source: docs.veracode.com/r/Scan_Web_Applications | F36: paper | Y36: =IF(ISBLANK(V36),"",V36-D36) | Z36: incremental-differential-scanning | AA36: 0 | AB36: =IF(ISBLANK(V36),D36,V36)
A37: Summary
A38: Coverage | C38: =SUMPRODUCT((B4:B36="Coverage")*C4:C36*AB4:AB36*(1-AA4:AA36))/5 | D38: =TEXT(C38,"0.0")&"/"&TEXT(E38,"0")&" available points" | E38: =SUMPRODUCT((B4:B36="Coverage")*C4:C36*(1-AA4:AA36))
A39: Detection Quality | C39: =SUMPRODUCT((B4:B36="Detection Quality")*C4:C36*AB4:AB36*(1-AA4:AA36))/5 | D39: =TEXT(C39,"0.0")&"/"&TEXT(E39,"0")&" available points" | E39: =SUMPRODUCT((B4:B36="Detection Quality")*C4:C36*(1-AA4:AA36))
A40: Production Safety & Operability | C40: =SUMPRODUCT((B4:B36="Production Safety & Operability")*C4:C36*AB4:AB36*(1-AA4:AA36))/5 | D40: =TEXT(C40,"0.0")&"/"&TEXT(E40,"0")&" available points" | E40: =SUMPRODUCT((B4:B36="Production Safety & Operability")*C4:C36*(1-AA4:AA36))
A41: Developer Experience | C41: =SUMPRODUCT((B4:B36="Developer Experience")*C4:C36*AB4:AB36*(1-AA4:AA36))/5 | D41: =TEXT(C41,"0.0")&"/"&TEXT(E41,"0")&" available points" | E41: =SUMPRODUCT((B4:B36="Developer Experience")*C4:C36*(1-AA4:AA36))
A42: Reporting & Extensibility | C42: =SUMPRODUCT((B4:B36="Reporting & Extensibility")*C4:C36*AB4:AB36*(1-AA4:AA36))/5 | D42: =TEXT(C42,"0.0")&"/"&TEXT(E42,"0")&" available points" | E42: =SUMPRODUCT((B4:B36="Reporting & Extensibility")*C4:C36*(1-AA4:AA36))
A43: Deployment & Data Governance | C43: =SUMPRODUCT((B4:B36="Deployment & Data Governance")*C4:C36*AB4:AB36*(1-AA4:AA36))/5 | D43: =TEXT(C43,"0.0")&"/"&TEXT(E43,"0")&" available points" | E43: =SUMPRODUCT((B4:B36="Deployment & Data Governance")*C4:C36*(1-AA4:AA36))
A44: Weighted Total | C44: =SUMPRODUCT(C4:C36,AB4:AB36,(1-AA4:AA36))/5 | D44: =TEXT(C44,"0.0")&"/"&TEXT(E44,"0")&" available points" | E44: =SUMPRODUCT(C4:C36,(1-AA4:AA36))

Sheet checkmarx-dast
A1: Checkmarx DAST
G2: =IF(Reviewers!B6="","Unassigned — see Reviewers tab",Reviewers!B6&" - "&Reviewers!C6) | J2: =IF(Reviewers!B7="","Unassigned — see Reviewers tab",Reviewers!B7&" - "&Reviewers!C7) | M2: =IF(Reviewers!B8="","Unassigned — see Reviewers tab",Reviewers!B8&" - "&Reviewers!C8) | P2: =IF(Reviewers!B9="","Unassigned — see Reviewers tab",Reviewers!B9&" - "&Reviewers!C9) | S2: =IF(Reviewers!B10="","Unassigned — see Reviewers tab",Reviewers!B10&" - "&Reviewers!C10)
A3: Criterion | B3: Category | C3: Weight | D3: Automated Score | E3: Automated Evidence | F3: Automated Confidence | G3: Score | H3: Dispute? | I3: Rationale | J3: Score | K3: Dispute? | L3: Rationale | M3: Score | N3: Dispute? | O3: Rationale | P3: Score | Q3: Dispute? | R3: Rationale | S3: Score | T3: Dispute? | U3: Rationale | V3: Resolved Score | W3: Resolved By | X3: Resolved Timestamp | Y3: Automated vs. Resolved Delta | Z3: _criterion_id | AA3: _pending | AB3: _effective_score
A4: Detection Accuracy | B4: Detection Quality | C4: 7 | D4: 3.5 | E4: Comprehensive OWASP Top 10 and OWASP API Top 10 coverage claimed, plus business-logic-aware testing -- but no independently published benchmark/ground-truth accuracy score found. Paper confidence, inferred from platform positioning rather than a cited third-party benchmark. Source: checkmarx.com/checkmarx-dast (vendor's own general accuracy/coverage claim, not an independent benchmark) | F4: paper | Y4: =IF(ISBLANK(V4),"",V4-D4) | Z4: detection-accuracy | AA4: 0 | AB4: =IF(ISBLANK(V4),D4,V4)
A5: Authentication & Session Handling | B5: Coverage | C5: 6 | D5: 4.5 | E5: Robust support: SSO via SAML/OAuth/OIDC, MFA/TOTP with token capture, browser-recorded scripted logins for multi-step/JS-heavy flows, session persistence across a scan. Source: docs.checkmarx.com/authentication-support, docs.checkmarx.com/sso-authentication | F5: paper | Y5: =IF(ISBLANK(V5),"",V5-D5) | Z5: auth-session-handling | AA5: 0 | AB5: =IF(ISBLANK(V5),D5,V5)
A6: Safe Production Scanning | B6: Production Safety & Operability | C6: 6 | D6: 4 | E6: Explicit production-safe, non-destructive testing mode with documented rate-limit configuration for complex applications. Source: docs.checkmarx.com/limiting-engine-scans, checkmarx.com/checkmarx-dast | F6: paper | Y6: =IF(ISBLANK(V6),"",V6-D6) | Z6: safe-prod-scanning | AA6: 0 | AB6: =IF(ISBLANK(V6),D6,V6)
A7: API/SPA Coverage | B7: Coverage | C7: 5 | D7: 3.5 | E7: REST/SOAP/gRPC endpoint testing confirmed, plus browser-recorded scripted logins for JS-heavy SPA auth flows -- but no confirmed GraphQL schema-introspection/fuzzing capability for Checkmarx-branded DAST specifically. Source: checkmarx.com/checkmarx-dast | F7: paper | Y7: =IF(ISBLANK(V7),"",V7-D7) | Z7: api-spa-coverage | AA7: 0 | AB7: =IF(ISBLANK(V7),D7,V7)
A8: CI/CD-Native Fit | B8: Production Safety & Operability | C8: 5 | D8: 4.5 | E8: Native plugins for major CI/CD platforms plus a CLI path for anything unsupported, with severity-threshold policy gating (e.g. fail build on Critical/High) as a documented, real control point. Source: docs.checkmarx.com/ci-cd-integrations, harness.io blog on Checkmarx One + Harness STO | F8: paper | Y8: =IF(ISBLANK(V8),"",V8-D8) | Z8: cicd-native-fit | AA8: 0 | AB8: =IF(ISBLANK(V8),D8,V8)
A9: Deployment Model & Data Residency | B9: Deployment & Data Governance | C9: 5 | D9: 4 | E9: SaaS, on-premises, and hybrid deployment models are all supported, including air-gapped for core scanning -- but newer ASPM/Assist/MCP-server features are documented as SaaS-only, a real limitation on the on-prem/air-gapped path. Source: securityscientist.net/blog/12-questions-and-answers-about-checkmarx-one | F9: paper | Y9: =IF(ISBLANK(V9),"",V9-D9) | Z9: deployment-model-data-residency | AA9: 0 | AB9: =IF(ISBLANK(V9),D9,V9)
A10: Legacy Application & Protocol Support | B10: Coverage | C10: 5 | D10: 4 | E10: Strong SOAP coverage confirmed (REST/SOAP/gRPC endpoint testing), reinforced by the underlying ZAP-derived engine's long OSS history of SOAP support (per Checkmarx's own scripting docs, not the separate standalone ZAP project) -- but no explicit claims found for ASP.NET WebForms/JSP/mainframe-gateway support specifically. Source: checkmarx.com/checkmarx-dast, docs.checkmarx.com/scripting | F10: paper | Y10: =IF(ISBLANK(V10),"",V10-D10) | Z10: legacy-app-protocol-support | AA10: 0 | AB10: =IF(ISBLANK(V10),D10,V10)
A11: Business Logic & Workflow Vulnerability Detection | B11: Coverage | C11: 4 | D11: 4 | E11: Explicit runtime business-logic testing for authorization bypass, privilege escalation, and transaction manipulation across multi-step workflows, including OWASP API Top 10 BOLA-class issues. Source: checkmarx.com/learn/integrating-dast-and-sast-into-devsecops-for-continuous-api-security | F11: paper | Y11: =IF(ISBLANK(V11),"",V11-D11) | Z11: business-logic-workflow-detection | AA11: 0 | AB11: =IF(ISBLANK(V11),D11,V11)
A12: Compliance & Standards Mapping | B12: Detection Quality | C12: 4 | D12: 3 | E12: OWASP Top 10 and OWASP API Security Top 10 mapping confirmed; no explicit PCI-DSS/GLBA/SOX/FFIEC/NYDFS regulatory-framework mapping found in DAST-specific documentation, though the platform broadly targets enterprise/regulated customers. Source: checkmarx.com/learn/integrating-dast-and-sast-into-devsecops-for-continuous-api-security | F12: paper | Y12: =IF(ISBLANK(V12),"",V12-D12) | Z12: compliance-standards-mapping | AA12: 0 | AB12: =IF(ISBLANK(V12),D12,V12)
A13: Noise / False-Positive Rate | B13: Detection Quality | C13: 4 | D13: 3.5 | E13: Proof-based scanning validates findings before flagging, and SAST-DAST correlation is cited to reduce noise -- but the vendor's own '89% noise reduction' figure applies to platform-wide ASPM correlation across all scanners, not a DAST-isolated false-positive rate, so it's cited here with that caveat rather than at face value. Source: checkmarx.com/blog/checkmarx-dast-for-the-ai-coding-era | F13: paper | Y13: =IF(ISBLANK(V13),"",V13-D13) | Z13: false-positive-rate | AA13: 0 | AB13: =IF(ISBLANK(V13),D13,V13)
A14: Shadow/Zombie API Discovery | B14: Coverage | C14: 4 | D14: 4 | E14: Bundled Checkmarx API Security module discovers shadow/zombie APIs via source-code scanning as code is committed -- source-level discovery rather than traffic-analysis/JS-bundle-parsing as the rubric's top tier envisions, but functionally a real continuous inventory. Source: checkmarx.com/product/api-security | F14: paper | Y14: =IF(ISBLANK(V14),"",V14-D14) | Z14: shadow-api-discovery | AA14: 0 | AB14: =IF(ISBLANK(V14),D14,V14)
A15: Triage & Remediation Guidance | B15: Developer Experience | C15: 4 | D15: 4 | E15: 'Developer Assist' agentic AI tool delivers real-time, context-aware remediation guidance inside the IDE. Source: docs.checkmarx.com (Checkmarx One Developer Assist) | F15: paper | Y15: =IF(ISBLANK(V15),"",V15-D15) | Z15: triage-remediation-guidance | AA15: 0 | AB15: =IF(ISBLANK(V15),D15,V15)
... A36: Incremental / Differential Scanning | B36: Production Safety & Operability | C36: 0 | D36: 1 | E36: Confirmed absent: Checkmarx's own support documentation states plainly that 'only API Security and SAST support incremental scans,' and selecting DAST for a scan run forces a full rescan instead. Independently gap-checked and confirmed by a fresh reviewer with a direct citation. Source: support.checkmarx.com | F36: paper | Y36: =IF(ISBLANK(V36),"",V36-D36) | Z36: incremental-differential-scanning | AA36: 0 | AB36: =IF(ISBLANK(V36),D36,V36)
A37: Summary
A38: Coverage | C38: =SUMPRODUCT((B4:B36="Coverage")*C4:C36*AB4:AB36*(1-AA4:AA36))/5 | D38: =TEXT(C38,"0.0")&"/"&TEXT(E38,"0")&" available points" | E38: =SUMPRODUCT((B4:B36="Coverage")*C4:C36*(1-AA4:AA36))
A39: Detection Quality | C39: =SUMPRODUCT((B4:B36="Detection Quality")*C4:C36*AB4:AB36*(1-AA4:AA36))/5 | D39: =TEXT(C39,"0.0")&"/"&TEXT(E39,"0")&" available points" | E39: =SUMPRODUCT((B4:B36="Detection Quality")*C4:C36*(1-AA4:AA36))
A40: Production Safety & Operability | C40: =SUMPRODUCT((B4:B36="Production Safety & Operability")*C4:C36*AB4:AB36*(1-AA4:AA36))/5 | D40: =TEXT(C40,"0.0")&"/"&TEXT(E40,"0")&" available points" | E40: =SUMPRODUCT((B4:B36="Production Safety & Operability")*C4:C36*(1-AA4:AA36))
A41: Developer Experience | C41: =SUMPRODUCT((B4:B36="Developer Experience")*C4:C36*AB4:AB36*(1-AA4:AA36))/5 | D41: =TEXT(C41,"0.0")&"/"&TEXT(E41,"0")&" available points" | E41: =SUMPRODUCT((B4:B36="Developer Experience")*C4:C36*(1-AA4:AA36))
A42: Reporting & Extensibility | C42: =SUMPRODUCT((B4:B36="Reporting & Extensibility")*C4:C36*AB4:AB36*(1-AA4:AA36))/5 | D42: =TEXT(C42,"0.0")&"/"&TEXT(E42,"0")&" available points" | E42: =SUMPRODUCT((B4:B36="Reporting & Extensibility")*C4:C36*(1-AA4:AA36))
A43: Deployment & Data Governance | C43: =SUMPRODUCT((B4:B36="Deployment & Data Governance")*C4:C36*AB4:AB36*(1-AA4:AA36))/5 | D43: =TEXT(C43,"0.0")&"/"&TEXT(E43,"0")&" available points" | E43: =SUMPRODUCT((B4:B36="Deployment & Data Governance")*C4:C36*(1-AA4:AA36))
A44: Weighted Total | C44: =SUMPRODUCT(C4:C36,AB4:AB36,(1-AA4:AA36))/5 | D44: =TEXT(C44,"0.0")&"/"&TEXT(E44,"0")&" available points" | E44: =SUMPRODUCT(C4:C36,(1-AA4:AA36))

Sheet hcl-appscan
A1: HCL AppScan
G2: =IF(Reviewers!B6="","Unassigned — see Reviewers tab",Reviewers!B6&" - "&Reviewers!C6) | J2: =IF(Reviewers!B7="","Unassigned — see Reviewers tab",Reviewers!B7&" - "&Reviewers!C7) | M2: =IF(Reviewers!B8="","Unassigned — see Reviewers tab",Reviewers!B8&" - "&Reviewers!C8) | P2: =IF(Reviewers!B9="","Unassigned — see Reviewers tab",Reviewers!B9&" - "&Reviewers!C9) | S2: =IF(Reviewers!B10="","Unassigned — see Reviewers tab",Reviewers!B10&" - "&Reviewers!C10)
A3: Criterion | B3: Category | C3: Weight | D3: Automated Score | E3: Automated Evidence | F3: Automated Confidence | G3: Score | H3: Dispute? | I3: Rationale | J3: Score | K3: Dispute? | L3: Rationale | M3: Score | N3: Dispute? | O3: Rationale | P3: Score | Q3: Dispute? | R3: Rationale | S3: Score | T3: Dispute? | U3: Rationale | V3: Resolved Score | W3: Resolved By | X3: Resolved Timestamp | Y3: Automated vs. Resolved Delta | Z3: _criterion_id | AA3: _pending | AB3: _effective_score
A4: Detection Accuracy | B4: Detection Quality | C4: 7 | D4: 3 | E4: An independent benchmark cites a 66% true-positive rate for critical vulnerabilities but only 60% accuracy in assigning correct severity -- real cited numbers, moderate rather than exceptional. Source: aimultiple.com/dast-tools benchmark | F4: paper | Y4: =IF(ISBLANK(V4),"",V4-D4) | Z4: detection-accuracy | AA4: 0 | AB4: =IF(ISBLANK(V4),D4,V4)
A5: Authentication & Session Handling | B5: Coverage | C5: 6 | D5: 4 | E5: SAML SSO, MFA/OTP, browser-based Recorded Login for scripted flows, and a Multi-Step Operations feature for sequence-dependent logins. Source: help.hcl-software.com SSO/OTP docs | F5: paper | Y5: =IF(ISBLANK(V5),"",V5-D5) | Z5: auth-session-handling | AA5: 0 | AB5: =IF(ISBLANK(V5),D5,V5)
A6: Safe Production Scanning | B6: Production Safety & Operability | C6: 6 | D6: 4 | E6: Documented max-request-rate configuration for production scans, explicit guidance to disable automatic form-fill in production to avoid flooding a database, and a passive IAST mode. Source: help.hcl-software.com production scanning guidance | F6: paper | Y6: =IF(ISBLANK(V6),"",V6-D6) | Z6: safe-prod-scanning | AA6: 0 | AB6: =IF(ISBLANK(V6),D6,V6)
A7: API/SPA Coverage | B7: Coverage | C7: 5 | D7: 3.5 | E7: REST/SOAP/GraphQL confirmed (GraphQL via template, Postman/SoapUI recording); one independent review notes GraphQL/gRPC support 'not as complete as competitors like StackHawk.' Source: help.hcl-software.com/appscan GraphQL template docs | F7: paper | Y7: =IF(ISBLANK(V7),"",V7-D7) | Z7: api-spa-coverage | AA7: 0 | AB7: =IF(ISBLANK(V7),D7,V7)
A8: CI/CD-Native Fit | B8: Production Safety & Operability | C8: 5 | D8: 4 | E8: Native Jenkins plugin, GitHub Actions action (appscan-dast-action), Azure DevOps and GitLab integrations; specific exit-code/policy-gate documentation less directly confirmed than for some competitors. Source: plugins.jenkins.io/appscan, github.com/HCL-TECH-SOFTWARE/appscan-gitlab-integration | F8: paper | Y8: =IF(ISBLANK(V8),"",V8-D8) | Z8: cicd-native-fit | AA8: 0 | AB8: =IF(ISBLANK(V8),D8,V8)
A9: Deployment Model & Data Residency | B9: Deployment & Data Governance | C9: 5 | D9: 4.5 | E9: Cloud, on-prem, sovereign cloud, hybrid, and air-gapped deployment options -- the most deployment-flexible of the four newly-added candidates. Source: hcl-software.com/appscan platform overview | F9: paper | Y9: =IF(ISBLANK(V9),"",V9-D9) | Z9: deployment-model-data-residency | AA9: 0 | AB9: =IF(ISBLANK(V9),D9,V9)
A10: Legacy Application & Protocol Support | B10: Coverage | C10: 5 | D10: 4.5 | E10: Deep SOAP support, long IBM/HCL AppScan lineage explicitly positioned for financial-services and healthcare legacy-compliance workflows -- likely the strongest of the newly-added candidates on this criterion. Source: appsecsanta.com/hcl-appscan-dast review | F10: paper | Y10: =IF(ISBLANK(V10),"",V10-D10) | Z10: legacy-app-protocol-support | AA10: 0 | AB10: =IF(ISBLANK(V10),D10,V10)
A11: Business Logic & Workflow Vulnerability Detection | B11: Coverage | C11: 4 | D11: 3 | E11: A documented 'Privilege Escalation' feature compares scan results across different authenticated user levels to detect broken access control -- real authorization-state-aware testing -- but distinct from and narrower than full BOLA-style dual-account object-ID comparison or generalized business-logic-workflow validation. Independently gap-checked, revised up from an initial 2.5. Source: help.hcl-software.com/appscan/Standard/10.6.0/t_TestPrivilegeEscalation080.html | F11: paper | Y11: =IF(ISBLANK(V11),"",V11-D11) | Z11: business-logic-workflow-detection | AA11: 0 | AB11: =IF(ISBLANK(V11),D11,V11)
A12: Compliance & Standards Mapping | B12: Detection Quality | C12: 4 | D12: 5 | E12: Built-in templates for PCI DSS, HIPAA, SOX, GDPR, plus a dedicated FFIEC compliance report and 40+ total compliance report types cited (including GLBA) -- directly hits the rubric's named regulatory frameworks. Source: help.hcl-software.com FFIEC report docs, help.hcl-software.com compliance policies | F12: paper | Y12: =IF(ISBLANK(V12),"",V12-D12) | Z12: compliance-standards-mapping | AA12: 0 | AB12: =IF(ISBLANK(V12),D12,V12)
A13: Noise / False-Positive Rate | B13: Detection Quality | C13: 4 | D13: 3 | E13: Same independent benchmark cites a 2% false-positive rate, but separate user reviews describe the false-positive rate as noticeably high, requiring manual rule adjustment -- genuinely conflicting evidence presented as such rather than picking the favorable number. Source: aimultiple.com/dast-tools | F13: paper | Y13: =IF(ISBLANK(V13),"",V13-D13) | Z13: false-positive-rate | AA13: 0 | AB13: =IF(ISBLANK(V13),D13,V13)
A14: Shadow/Zombie API Discovery | B14: Coverage | C14: 4 | D14: 4 | E14: AppScan API Security (built with Salt Security) does AI-driven, traffic-based discovery of shadow and zombie APIs. Source: hcl-software.com/appscan/products/api-security | F14: paper | Y14: =IF(ISBLANK(V14),"",V14-D14) | Z14: shadow-api-discovery | AA14: 0 | AB14: =IF(ISBLANK(V14),D14,V14)
A15: Triage & Remediation Guidance | B15: Developer Experience | C15: 4 | D15: 4 | E15: RapidFix delivers AI-driven fix suggestions with human-verified recommendations, plus a documented remediation-task workflow in AppScan Standard (the DAST product). Source: hcl-software.com/appscan/products/rapidfix | F15: paper | Y15: =IF(ISBLANK(V15),"",V15-D15) | Z15: triage-remediation-guidance | AA15: 0 | AB15: =IF(ISBLANK(V15),D15,V15)
... A36: Incremental / Differential Scanning | B36: Production Safety & Operability | C36: 0 | D36: 4.5 | E36: Confirmed present for DAST after independent gap-check: AppScan on Cloud/360 documentation explicitly describes a DAST 'Incremental scan' mode that scans only the parts of the application that changed since the last scan, with an Explore stage to detect new/changed structure. Source: help.hcl-software.com/appscan/ASoC/appseccloud_scanning_rescan_cm.html, help.hcl-software.com/appscan/360/1.4.0/Incremental.html | F36: paper | Y36: =IF(ISBLANK(V36),"",V36-D36) | Z36: incremental-differential-scanning | AA36: 0 | AB36: =IF(ISBLANK(V36),D36,V36)
A37: Summary
A38: Coverage | C38: =SUMPRODUCT((B4:B36="Coverage")*C4:C36*AB4:AB36*(1-AA4:AA36))/5 | D38: =TEXT(C38,"0.0")&"/"&TEXT(E38,"0")&" available points" | E38: =SUMPRODUCT((B4:B36="Coverage")*C4:C36*(1-AA4:AA36))
A39: Detection Quality | C39: =SUMPRODUCT((B4:B36="Detection Quality")*C4:C36*AB4:AB36*(1-AA4:AA36))/5 | D39: =TEXT(C39,"0.0")&"/"&TEXT(E39,"0")&" available points" | E39: =SUMPRODUCT((B4:B36="Detection Quality")*C4:C36*(1-AA4:AA36))
A40: Production Safety & Operability | C40: =SUMPRODUCT((B4:B36="Production Safety & Operability")*C4:C36*AB4:AB36*(1-AA4:AA36))/5 | D40: =TEXT(C40,"0.0")&"/"&TEXT(E40,"0")&" available points" | E40: =SUMPRODUCT((B4:B36="Production Safety & Operability")*C4:C36*(1-AA4:AA36))
A41: Developer Experience | C41: =SUMPRODUCT((B4:B36="Developer Experience")*C4:C36*AB4:AB36*(1-AA4:AA36))/5 | D41: =TEXT(C41,"0.0")&"/"&TEXT(E41,"0")&" available points" | E41: =SUMPRODUCT((B4:B36="Developer Experience")*C4:C36*(1-AA4:AA36))
A42: Reporting & Extensibility | C42: =SUMPRODUCT((B4:B36="Reporting & Extensibility")*C4:C36*AB4:AB36*(1-AA4:AA36))/5 | D42: =TEXT(C42,"0.0")&"/"&TEXT(E42,"0")&" available points" | E42: =SUMPRODUCT((B4:B36="Reporting & Extensibility")*C4:C36*(1-AA4:AA36))
A43: Deployment & Data Governance | C43: =SUMPRODUCT((B4:B36="Deployment & Data Governance")*C4:C36*AB4:AB36*(1-AA4:AA36))/5 | D43: =TEXT(C43,"0.0")&"/"&TEXT(E43,"0")&" available points" | E43: =SUMPRODUCT((B4:B36="Deployment & Data Governance")*C4:C36*(1-AA4:AA36))
A44: Weighted Total | C44: =SUMPRODUCT(C4:C36,AB4:AB36,(1-AA4:AA36))/5 | D44: =TEXT(C44,"0.0")&"/"&TEXT(E44,"0")&" available points" | E44: =SUMPRODUCT(C4:C36,(1-AA4:AA36))

Sheet stackhawk
A1: StackHawk
G2: =IF(Reviewers!B6="","Unassigned — see Reviewers tab",Reviewers!B6&" - "&Reviewers!C6) | J2: =IF(Reviewers!B7="","Unassigned — see Reviewers tab",Reviewers!B7&" - "&Reviewers!C7) | M2: =IF(Reviewers!B8="","Unassigned — see Reviewers tab",Reviewers!B8&" - "&Reviewers!C8) | P2: =IF(Reviewers!B9="","Unassigned — see Reviewers tab",Reviewers!B9&" - "&Reviewers!C9) | S2: =IF(Reviewers!B10="","Unassigned — see Reviewers tab",Reviewers!B10&" - "&Reviewers!C10)
A3: Criterion | B3: Category | C3: Weight | D3: Automated Score | E3: Automated Evidence | F3: Automated Confidence | G3: Score | H3: Dispute? | I3: Rationale | J3: Score | K3: Dispute? | L3: Rationale | M3: Score | N3: Dispute? | O3: Rationale | P3: Score | Q3: Dispute? | R3: Rationale | S3: Score | T3: Dispute? | U3: Rationale | V3: Resolved Score | W3: Resolved By | X3: Resolved Timestamp | Y3: Automated vs. Resolved Delta | Z3: _criterion_id | AA3: _pending | AB3: _effective_score
A4: Detection Accuracy | B4: Detection Quality | C4: 7 | D4: 4 | E4: VENDOR CLAIM, not independently verified. HawkScan runs real attacks against the live app; dedicated Intelligent Business Logic Testing feature specifically targets authorization/logic flaws -- notable vs ZAP/Nuclei. Documented engineering-level detection refinements (e.g. correctly distinguishing true/false boolean-blind-SQLi condition responses) show ongoing tuning, but all from StackHawk's own materials. Source: docs.stackhawk.com/changelog.html | F4: paper | Y4: =IF(ISBLANK(V4),"",V4-D4) | Z4: detection-accuracy | AA4: 0 | AB4: =IF(ISBLANK(V4),D4,V4)
A5: Safe Production Scanning | B5: Production Safety & Operability | C5: 6 | D5: 4.5 | E5: Documented granular config: requestDelayMillis, concurrentRequests, throttlePassiveBacklog, throttleIntervalSeconds, maxDurationMinutes/maxRuleDurationMinutes, plus a dedicated 'Production Safe' scan policy. Source: docs.stackhawk.com/hawkscan/configuration, docs.stackhawk.com/platform/policy-management/production-safe-scanning | F5: paper | Y5: =IF(ISBLANK(V5),"",V5-D5) | Z5: safe-prod-scanning | AA5: 0 | AB5: =IF(ISBLANK(V5),D5,V5)
A6: Authentication & Session Handling | B6: Coverage | C6: 6 | D6: 4.5 | E6: JSON/form-based auth plus 3rd-party OAuth 2.0 identity providers (Auth0, Okta, Firebase, KeyCloak) directly configurable in the YAML config, with external token injection available for custom scenarios outside the scanner -- strong, low-friction, well-documented. Source: docs.stackhawk.com/getting-started/auth-scan.html | F6: paper | Y6: =IF(ISBLANK(V6),"",V6-D6) | Z6: auth-session-handling | AA6: 0 | AB6: =IF(ISBLANK(V6),D6,V6)
A7: Deployment Model & Data Residency | B7: Deployment & Data Governance | C7: 5 | D7: 2 | E7: Cloud-only execution (config-as-code + cloud backend, Tier 2 per dast-onboard-tool's tiering); no on-prem or configurable data-residency option found. Source: appsecsanta.com (independent review states StackHawk is SaaS-only with no on-prem/air-gapped option, contrasted against Invicti which offers on-prem) | F7: paper | Y7: =IF(ISBLANK(V7),"",V7-D7) | Z7: deployment-model-data-residency | AA7: 0 | AB7: =IF(ISBLANK(V7),D7,V7)
A8: API/SPA Coverage | B8: Coverage | C8: 5 | D8: 4 | E8: Native REST/GraphQL/SOAP/gRPC, introspection-driven GraphQL test generation. API coverage excellent; JS-rendered SPA-UI crawling not emphasized in their docs (spec-driven, not crawl-driven). Source: stackhawk.com/blog/graphql-security | F8: paper | Y8: =IF(ISBLANK(V8),"",V8-D8) | Z8: api-spa-coverage | AA8: 0 | AB8: =IF(ISBLANK(V8),D8,V8)
A9: CI/CD-Native Fit | B9: Production Safety & Operability | C9: 5 | D9: 5 | E9: Core value prop -- YAML config-as-code, deliberately CI-native exit-code design: exit 42 specifically when the configured failure threshold is reached (distinguishable from exit 1 for an actual scan error). Source: docs.stackhawk.com/getting-started | F9: paper | Y9: =IF(ISBLANK(V9),"",V9-D9) | Z9: cicd-native-fit | AA9: 0 | AB9: =IF(ISBLANK(V9),D9,V9)
A10: Legacy Application & Protocol Support | B10: Coverage | C10: 5 | D10: 3 | E10: Explicit SOAP support alongside REST/GraphQL/gRPC (SOAP is often legacy-adjacent); no legacy-framework-specific (older Microsoft web forms, JSP) testing confirmed. Source: stackhawk.com/solutions/dast | F10: paper | Y10: =IF(ISBLANK(V10),"",V10-D10) | Z10: legacy-app-protocol-support | AA10: 0 | AB10: =IF(ISBLANK(V10),D10,V10)
A11: Shadow/Zombie API Discovery | B11: Coverage | C11: 4 | D11: 3.5 | E11: Named 'API Discovery'/HawkAI feature statically parses connected source repos (GitHub/GitLab/Bitbucket/Azure Repos) to find endpoints missing from OpenAPI specs across Express/Spring/Django/Rails/etc. Source-code-based, not traffic-analysis/JS-bundle-parsing as the rubric's top tier specifies, and no evidence it flags deprecated/versioned endpoints specifically. Source: docs.stackhawk.com/web-app/api-discovery.html, stackhawk.com/product/api-discovery | F11: paper | Y11: =IF(ISBLANK(V11),"",V11-D11) | Z11: shadow-api-discovery | AA11: 0 | AB11: =IF(ISBLANK(V11),D11,V11)
A12: Business Logic & Workflow Vulnerability Detection | B12: Coverage | C12: 4 | D12: 4.5 | E12: 'Intelligent Business Logic Testing' -- explicit, purpose-built multi-profile/multi-user-perspective testing for authorization flaws (BOLA-style), StackHawk's own marketed differentiator. Source: stackhawk.com/blog/business-logic-testing, docs.stackhawk.com/hawkscan/business-logic-testing | F12: paper | Y12: =IF(ISBLANK(V12),"",V12-D12) | Z12: business-logic-workflow-detection | AA12: 0 | AB12: =IF(ISBLANK(V12),D12,V12)
A13: Compliance & Standards Mapping | B13: Detection Quality | C13: 4 | D13: 4.5 | E13: Explicit, well-documented pre-built compliance reports for PCI-DSS, HIPAA, and SOC 2, including a dedicated PCI DSS v4.0.1 mapping blog post -- best-documented of the three candidates on this point. Source: stackhawk.com/blog/pci-dss-appsec-compliance | F13: paper | Y13: =IF(ISBLANK(V13),"",V13-D13) | Z13: compliance-standards-mapping | AA13: 0 | AB13: =IF(ISBLANK(V13),D13,V13)
A14: Noise / False-Positive Rate | B14: Detection Quality | C14: 4 | D14: 4 | E14: VENDOR CLAIM. Runtime testing against the live app (not code patterns) reduces FPs per their own materials; documented specific improvements (stripping query/form parameter values to reduce SQLi false positives on input-validated apps) are more concrete than generic marketing, though still first-party and not independently verified. Source: docs.stackhawk.com/changelog.html | F14: paper | Y14: =IF(ISBLANK(V14),"",V14-D14) | Z14: false-positive-rate | AA14: 0 | AB14: =IF(ISBLANK(V14),D14,V14)
A15: Triage & Remediation Guidance | B15: Developer Experience | C15: 4 | D15: 4.5 | E15: Remediation guidance is written in the target language with code-level, framework-tailored context, not generic security jargon -- fixes can be reviewed and applied directly in the editor. Source: stackhawk.com/blog/how-does-stackhawk-work | F15: paper | Y15: =IF(ISBLANK(V15),"",V15-D15) | Z15: triage-remediation-guidance | AA15: 0 | AB15: =IF(ISBLANK(V15),D15,V15)
... A36: Incremental / Differential Scanning | B36: Production Safety & Operability | C36: 0 | D36: 3 | E36: Documented includePaths/excludePaths scan-scoping config in stackhawk.yml matches rubric level 3 exactly. Marketing phrase 'fast incremental scans' has no accompanying technical documentation of automatic changed-code detection. Source: docs.stackhawk.com/hawkscan/configuration | F36: paper | Y36: =IF(ISBLANK(V36),"",V36-D36) | Z36: incremental-differential-scanning | AA36: 0 | AB36: =IF(ISBLANK(V36),D36,V36)
A37: Summary
A38: Coverage | C38: =SUMPRODUCT((B4:B36="Coverage")*C4:C36*AB4:AB36*(1-AA4:AA36))/5 | D38: =TEXT(C38,"0.0")&"/"&TEXT(E38,"0")&" available points" | E38: =SUMPRODUCT((B4:B36="Coverage")*C4:C36*(1-AA4:AA36))
A39: Detection Quality | C39: =SUMPRODUCT((B4:B36="Detection Quality")*C4:C36*AB4:AB36*(1-AA4:AA36))/5 | D39: =TEXT(C39,"0.0")&"/"&TEXT(E39,"0")&" available points" | E39: =SUMPRODUCT((B4:B36="Detection Quality")*C4:C36*(1-AA4:AA36))
A40: Production Safety & Operability | C40: =SUMPRODUCT((B4:B36="Production Safety & Operability")*C4:C36*AB4:AB36*(1-AA4:AA36))/5 | D40: =TEXT(C40,"0.0")&"/"&TEXT(E40,"0")&" available points" | E40: =SUMPRODUCT((B4:B36="Production Safety & Operability")*C4:C36*(1-AA4:AA36))
A41: Developer Experience | C41: =SUMPRODUCT((B4:B36="Developer Experience")*C4:C36*AB4:AB36*(1-AA4:AA36))/5 | D41: =TEXT(C41,"0.0")&"/"&TEXT(E41,"0")&" available points" | E41: =SUMPRODUCT((B4:B36="Developer Experience")*C4:C36*(1-AA4:AA36))
A42: Reporting & Extensibility | C42: =SUMPRODUCT((B4:B36="Reporting & Extensibility")*C4:C36*AB4:AB36*(1-AA4:AA36))/5 | D42: =TEXT(C42,"0.0")&"/"&TEXT(E42,"0")&" available points" | E42: =SUMPRODUCT((B4:B36="Reporting & Extensibility")*C4:C36*(1-AA4:AA36))
A43: Deployment & Data Governance | C43: =SUMPRODUCT((B4:B36="Deployment & Data Governance")*C4:C36*AB4:AB36*(1-AA4:AA36))/5 | D43: =TEXT(C43,"0.0")&"/"&TEXT(E43,"0")&" available points" | E43: =SUMPRODUCT((B4:B36="Deployment & Data Governance")*C4:C36*(1-AA4:AA36))
A44: Weighted Total | C44: =SUMPRODUCT(C4:C36,AB4:AB36,(1-AA4:AA36))/5 | D44: =TEXT(C44,"0.0")&"/"&TEXT(E44,"0")&" available points" | E44: =SUMPRODUCT(C4:C36,(1-AA4:AA36))

Sheet zap
A1: OWASP ZAP
G2: =IF(Reviewers!B6="","Unassigned — see Reviewers tab",Reviewers!B6&" - "&Reviewers!C6) | J2: =IF(Reviewers!B7="","Unassigned — see Reviewers tab",Reviewers!B7&" - "&Reviewers!C7) | M2: =IF(Reviewers!B8="","Unassigned — see Reviewers tab",Reviewers!B8&" - "&Reviewers!C8) | P2: =IF(Reviewers!B9="","Unassigned — see Reviewers tab",Reviewers!B9&" - "&Reviewers!C9) | S2: =IF(Reviewers!B10="","Unassigned — see Reviewers tab",Reviewers!B10&" - "&Reviewers!C10)
A3: Criterion | B3: Category | C3: Weight | D3: Automated Score | E3: Automated Evidence | F3: Automated Confidence | G3: Score | H3: Dispute? | I3: Rationale | J3: Score | K3: Dispute? | L3: Rationale | M3: Score | N3: Dispute? | O3: Rationale | P3: Score | Q3: Dispute? | R3: Rationale | S3: Score | T3: Dispute? | U3: Rationale | V3: Resolved Score | W3: Resolved By | X3: Resolved Timestamp | Y3: Automated vs. Resolved Delta | Z3: _criterion_id | AA3: _pending | AB3: _effective_score
A4: Detection Accuracy | B4: Detection Quality | C4: 7 | D4: 3.5 | E4: Aggregate hands-on: 11/15 (73%) known vulnerabilities detected across Juice Shop (8/10) and VAmPI (3/5), against ground truth rebuilt from real observed output. Solid coverage of misconfiguration/header-level issues; refines the earlier paper score (3.5, unchanged) with real evidence. | F4: hands-on | Y4: =IF(ISBLANK(V4),"",V4-D4) | Z4: detection-accuracy | AA4: 0 | AB4: =IF(ISBLANK(V4),D4,V4)
A5: Authentication & Session Handling | B5: Coverage | C5: 6 | D5: 3.5 | E5: Native authentication methods (browser-based, client script, form-based, JSON-based, auto-detect) plus session management (header/cookie-based, auto-detect); Client Script (Zest) authentication automates complex/custom login flows since there's no dedicated native SSO/OAuth/MFA auth type -- solid but requires manual scripting for anything beyond the built-in methods. Source: deepwiki.com/zaproxy/zap-extensions/2.3-authentication-and-session-management | F5: paper | Y5: =IF(ISBLANK(V5),"",V5-D5) | Z5: auth-session-handling | AA5: 0 | AB5: =IF(ISBLANK(V5),D5,V5)
A6: Safe Production Scanning | B6: Production Safety & Operability | C6: 6 | D6: 4.5 | E6: Passive-only proxying explicitly documented as safe for production; dedicated safe/protected modes; configurable rate limiting (Network > Rate Limit). Source: zaproxy.org/faq/is-there-any-danger-when-scanning-with-zap | F6: paper | Y6: =IF(ISBLANK(V6),"",V6-D6) | Z6: safe-prod-scanning | AA6: 0 | AB6: =IF(ISBLANK(V6),D6,V6)
A7: API/SPA Coverage | B7: Coverage | C7: 5 | D7: 4 | E7: REST/GraphQL/SOAP via Automation Framework + dedicated GraphQL add-on (introspection + query fuzzing), AJAX Spider for headless JS-SPA crawling. GraphQL deep testing sometimes needs custom scripts, not fully automatic. Source: zaproxy.org/docs/desktop/addons/graphql-support | F7: paper | Y7: =IF(ISBLANK(V7),"",V7-D7) | Z7: api-spa-coverage | AA7: 0 | AB7: =IF(ISBLANK(V7),D7,V7)
A8: CI/CD-Native Fit | B8: Production Safety & Operability | C8: 5 | D8: 5 | E8: First-class docker automation via the zap-full-scan.py script (ghcr.io/zaproxy/zaproxy:stable image) plus the newer YAML-based Automation Framework covering contexts, authentication, spider, active scan, and report generation as discrete jobs -- this project's own CI pipeline uses it directly. Source: zaproxy.org/docs/docker | F8: paper | Y8: =IF(ISBLANK(V8),"",V8-D8) | Z8: cicd-native-fit | AA8: 0 | AB8: =IF(ISBLANK(V8),D8,V8)
A9: Deployment Model & Data Residency | B9: Deployment & Data Governance | C9: 5 | D9: 5 | E9: Runs entirely self-hosted -- desktop app, the official docker image, or CLI -- with no SaaS/cloud-backend component at all, so all scan data and traffic stay wherever it's run, inherently on-prem/air-gap-capable by nature rather than by a configured deployment option. Source: zaproxy.org/docs/docker | F9: paper | Y9: =IF(ISBLANK(V9),"",V9-D9) | Z9: deployment-model-data-residency | AA9: 0 | AB9: =IF(ISBLANK(V9),D9,V9)
A10: Legacy Application & Protocol Support | B10: Coverage | C10: 5 | D10: 4 | E10: Founded in 2010 as a fork of Paros Proxy, ZAP was originally a general-purpose HTTP(S) intercepting proxy/scanner predating SPA-era tooling, making it inherently protocol/framework-agnostic for classic server-rendered legacy applications; SPA-specific crawling (AJAX Spider) was added later as an add-on. Source: en.wikipedia.org/wiki/ZAP_(software) | F10: paper | Y10: =IF(ISBLANK(V10),"",V10-D10) | Z10: legacy-app-protocol-support | AA10: 0 | AB10: =IF(ISBLANK(V10),D10,V10)
A11: Business Logic & Workflow Vulnerability Detection | B11: Coverage | C11: 4 | D11: 3.5 | E11: ZAP's 'Access Control Testing' add-on defines per-role Access Rules within a Context, then automatically attacks every discovered URL as each configured user to flag authorization violations -- genuine authorization-state tracking across roles. Does not do true multi-step/sequence-dependent workflow chains; ZAP is independently documented to struggle with business logic flaws generally. Source: zaproxy.org/docs/desktop/addons/access-control-testing | F11: paper | Y11: =IF(ISBLANK(V11),"",V11-D11) | Z11: business-logic-workflow-detection | AA11: 0 | AB11: =IF(ISBLANK(V11),D11,V11)
A12: Vulnerability Status Management | B12: Reporting & Extensibility | C12: 4 | D12: 1 | E12: No exception/risk-acceptance workflow or audit trail for finding lifecycle -- a scan-and-report tool, not a vulnerability management platform. Source: zaproxy.org/docs (ZAP itself has no lifecycle workflow beyond a flat alert list; the only related evidence found, Checkmarx One's triage states/audit trail, is that separate paid platform's feature) | F12: paper | Y12: =IF(ISBLANK(V12),"",V12-D12) | Z12: vulnerability-status-management | AA12: 0 | AB12: =IF(ISBLANK(V12),D12,V12)
A13: Compliance & Standards Mapping | B13: Detection Quality | C13: 4 | D13: 3.5 | E13: Real cweid/wascid mapping per plugin and OWASP Top 10 tagging used for compliance reporting (SOC2/PCI-DSS), but mapping coverage is incomplete across all plugins per ZAP's own developers; no financial-services-specific (GLBA/SOX/FFIEC/NYDFS) tagging out of the box. Source: zaproxy.org/docs/alerts, ZAP developer mailing list discussion on OWASP Top 10 mapping completeness. | F13: paper | Y13: =IF(ISBLANK(V13),"",V13-D13) | Z13: compliance-standards-mapping | AA13: 0 | AB13: =IF(ISBLANK(V13),D13,V13)
A14: Noise / False-Positive Rate | B14: Detection Quality | C14: 4 | D14: 3.5 | E14: Aggregate hands-on: 5 false positives against 11 real detections across both targets -- a manageable ratio, refining the earlier paper score (3, now 3.5) with real evidence. | F14: hands-on | Y14: =IF(ISBLANK(V14),"",V14-D14) | Z14: false-positive-rate | AA14: 0 | AB14: =IF(ISBLANK(V14),D14,V14)
A15: Shadow/Zombie API Discovery | B15: Coverage | C15: 4 | D15: 3 | E15: AJAX Spider (built on the Crawljax engine) executes JavaScript to discover new paths/API routes in SPA/AJAX applications; no dedicated deprecated/versioned-endpoint detection engine confirmed beyond that JS-execution-based path discovery. Source: zaproxy.org/docs/desktop/addons/ajax-spider | F15: paper | Y15: =IF(ISBLANK(V15),"",V15-D15) | Z15: shadow-api-discovery | AA15: 0 | AB15: =IF(ISBLANK(V15),D15,V15)
... A36: Incremental / Differential Scanning | B36: Production Safety & Operability | C36: 0 | D36: 3 | E36: ZAP's 'Contexts' feature lets users explicitly include/exclude URL patterns to scope a scan to specific paths, directly matching rubric level 3. No automatic change-detection-since-last-scan capability found. Source: zaproxy.org/docs/desktop/start/features/contexts | F36: paper | Y36: =IF(ISBLANK(V36),"",V36-D36) | Z36: incremental-differential-scanning | AA36: 0 | AB36: =IF(ISBLANK(V36),D36,V36)
A37: Summary
